<mujoco model="inspire_hand_r">
        <compiler angle="radian" />
        <option integrator="RK4" timestep= "0.001" /> 
        <!-- <option apirate="200" iterations="20" noslip_iterations="20" cone="elliptic" solver="PGS"/>      -->
        <size njmax="2000" nconmax="500" nstack="600000"/>
        <!-- <size njmax="2000" nconmax="500" nstack="600000" nuser_body="9" nuser_jnt="1" nuser_site="1" nuser_tendon="1"
                nuser_actuator="16" nuser_sensor="1"/> -->
        <default class="main">
                <default class="D_Touch">
                        <site size="0.009 0.004 0.013" group="4" type="box" rgba="0.8 0.8 0.8 0.15"/>
                </default>
                <default class="DC_Hand">
                        <!-- <geom contype="1" conaffinity="1" group="4" friction="1 0.5 0.01" margin="0.0005"/> -->
                        <geom contype="1" conaffinity="1" group="4" friction="1 0.5 0.01" margin="0.0001"/>
                </default>
                <default class="D_Vizual">
                        <!-- <geom type="mesh" contype="1" conaffinity="1" group="1" friction="1 0.5 0.01" margin="0.0005"/> -->
                        <geom type="mesh" conaffinity="1" group="1" friction="1 0.5 0.01" margin="0.0001"/>
                </default>
        </default>


        <asset>
                <mesh name="R_hand_base_link" file="../meshes/R_hand_base_link.STL" />
                <mesh name="R_thumb_proximal_base" file="../meshes/R_thumb_proximal_base.STL" />
                <mesh name="R_thumb_proximal" file="../meshes/R_thumb_proximal.STL" />
                <mesh name="R_thumb_intermediate" file="../meshes/R_thumb_intermediate.STL" />
                <mesh name="R_thumb_distal" file="../meshes/R_thumb_distal.STL" />
                <mesh name="R_index_proximal" file="../meshes/R_index_proximal.STL" />
                <mesh name="R_index_distal" file="../meshes/R_index_distal.STL" />
                <mesh name="R_middle_proximal" file="../meshes/R_middle_proximal.STL" />
                <mesh name="R_middle_distal" file="../meshes/R_middle_distal.STL" />
                <mesh name="R_ring_proximal" file="../meshes/R_ring_proximal.STL" />
                <mesh name="R_ring_distal" file="../meshes/R_ring_distal.STL" />
                <mesh name="R_pinky_proximal" file="../meshes/R_pinky_proximal.STL" />
                <mesh name="R_pinky_distal" file="../meshes/R_pinky_distal.STL" />
        </asset>
        
        <worldbody>
                <body name="hand" pos="-0.47 -0.75 -0.5" >
                        <inertial pos="0.42 0.5 0.75" quat="0.982037 -0.0160006 0 -0.188007" mass="3" diaginertia="0.01 0.01 0.0075"/>
                        <joint name="ARTx" pos="0.42 0.4 0.75" axis="-1 0 0" type="slide" range="-0.75 0.75" damping="20" limited="true" margin="0.01" 
                                armature="0.001" frictionloss="0.001"/>
                        <joint name="ARTy" pos="0.42 0.4 0.75" axis="0 0 1" type="slide" range="-0.75 0.75" damping="20" limited="true" margin="0.01"
                                armature="0.001" frictionloss="0.001"/>
                        <joint name="ARTz" pos="0.42 0.4 0.75" axis="0 1 0" type="slide" range="-0.75 0.75" damping="20" limited="true" margin="0.01" 
                                armature="0.001" frictionloss="0.001"/> 
                        <joint name="ARRx" pos="0.42 0.42 0.75" axis="-1 0 0" range="-2.75 2.75" damping="20" limited="true" margin="0.01"
                                armature="0.001" frictionloss="0.001"/>
                        <joint name="ARRy" pos="0.42 0.42 0.75" axis="0 0 1" range="-2.75 2.75" damping="20" limited="true" margin="0.01"
                                armature="0.001" frictionloss="0.001"/>
                        <joint name="ARRz" pos="0.42 0.42 0.75" axis="0 1 0" range="-2.75 2.75" damping="20" limited="true" margin="0.01"
                                armature="0.001" frictionloss="0.001"/> 

                        <geom name="C_hand" class="DC_Hand"  pos="0.5 0.5 0.5" quat="0.707107 -0.707107 0 0" type="mesh" rgba="1 1 1 1" mesh="R_hand_base_link" />
                        <geom name="V_hand" class="D_Vizual" pos="0.5 0.5 0.5" quat="0.707107 -0.707107 0 0" type="mesh" contype="0" conaffinity="0" group="1" rgba="1 1 1 1" mesh="R_hand_base_link" />

                        <site name="S_grasp" pos="0.007 -0.05 0.07" quat="0.00863043 -0.595202 -0.00337281 -0.803523" size="0.01"
                                rgba="0 0 0 0"/>
                        <!-- <site name="Tch_ffmetacarpal" class="D_Touch" pos="0.033 -0.008 0.078" size="0.009 0.004 0.006"/>
                        <site name="Tch_mfmetacarpal" class="D_Touch" pos="0.011 -0.008 0.074" size="0.009 0.004 0.014"/>
                        <site name="Tch_rfmetacarpal" class="D_Touch" pos="-0.011 -0.008 0.068" size="0.009 0.004 0.016"/>
                        <site name="Tch_thmetacarpal" class="D_Touch" pos="0.006 -0.008 0.042" quat="0.959662 0 0.281157 0"
                                size="0.008 0.004 0.015"/>
                        <site name="Tch_palm" class="D_Touch" pos="-0.017 -0.008 0.024" quat="0.877583 0 -0.479426 0"
                                size="0.012 0.004 0.016"/> -->
                                
                        <body name="R_thumb_proximal_base" pos="0.401367 0.488636 0.73173" quat="0.990013 1.83152e-06 -0.140974 2.57024e-07">
                                <inertial pos="-0.0048772 -0.010163 0.00044069" quat="0.075637 0.631378 -0.107678 0.764229" mass="0.0018869" diaginertia="8.66028e-08 6.87321e-08 4.94192e-08" />
                                <joint name="R_thumb_MCP_joint1" pos="0 0 0" axis="0 -1 0" limited="true" range="0.2 1.3" armature="0.001" damping="0.05" frictionloss="0.001"/>
                                <geom name="C_thumb_proximal_base" class="DC_Hand"  type="mesh" contype="0" conaffinity="0" group="1" rgba="1 1 1 1" mesh="R_thumb_proximal_base" />
                                <geom name="V_thumb_proximal_base" class="D_Vizual" type="mesh" rgba="1 1 1 1" mesh="R_thumb_proximal_base" />
                                <body name="R_thumb_proximal" pos="-0.0115 -0.011843 0" quat="-0.6554345 0.2653441 -0.6554321 -0.2653431">
                                        <inertial pos="-3.8592e-05 0.02533 -0.0017007" quat="0.656826 0.754039 0.00146914 -0.00128614" mass="0.0066075" diaginertia="2.78601e-06 2.43932e-06 8.64597e-07" />
                                        <joint name="R_thumb_MCP_joint2" pos="0 0 0" axis="1 0 0" limited="true" range="0 1.8" armature="0.001" damping="0.05" frictionloss="0.001"/>
                                        <geom name="C_thumb_proximal" class="DC_Hand"  type="mesh" contype="0" conaffinity="0" group="1" rgba="1 1 1 1" mesh="R_thumb_proximal" />
                                        <geom name="V_thumb_proximal" class="D_Vizual" type="mesh" rgba="1 1 1 1" mesh="R_thumb_proximal" />
                                        <site name="S_thumb_bottom" pos="0 0 0.026" group="3" size="0.005 0 0" rgba="0.4 0.9 0.4 1"/>
                                        <site name="Tch_thumb_bottom" class="D_Touch" pos="0 -0.004 0.018"/>   

                                        <body name="R_thumb_intermediate" pos="0 0.055863 0.0039241" quat="0.999817 -0.0191483 0 0">
                                                <inertial pos="2.8437e-07 0.0072526 -0.0064293" quat="0.575988 0.817458 -0.000107087 6.96147e-05" mass="0.0037847" diaginertia="4.6531e-07 4.48088e-07 2.45662e-07" />
                                                <joint name="R_thumb_PIP_joint" pos="0 0 0" axis="1 0 0" limited="true" range="0 1" armature="0.001" damping="0.05" frictionloss="0.001"/>
                                                <geom name="C_thumb_intermediate" class="DC_Hand"  type="mesh" rgba="1 1 1 1" mesh="R_thumb_intermediate" />
                                                <geom name="V_thumb_intermediate" class="D_Vizual" type="mesh" contype="0" conaffinity="0" group="1" rgba="1 1 1 1" mesh="R_thumb_intermediate" />
                                                <body name="R_thumb_distal" pos="0 0.022558 -0.0020717" quat="0.999983 -0.00582097 0 0">
                                                        <inertial pos="-3.3054e-06 0.010511 -0.00057863" quat="0.624404 0.781098 0.00147531 -0.00199963" mass="0.0033441" diaginertia="2.0026e-07 1.95252e-07 8.15973e-08" />
                                                        <joint name="R_thumb_DIP_joint" pos="0 0 0" axis="1 0 0" limited="true" range="0 1.2" armature="0.001" damping="0.05" frictionloss="0.001"/>
                                                        <geom name="C_thumb_distal" class="DC_Hand"  type="mesh" contype="0" conaffinity="0" group="1" rgba="1 1 1 1" mesh="R_thumb_distal" />
                                                        <geom name="V_thumb_distal" class="D_Vizual" type="mesh" rgba="1 1 1 1" mesh="R_thumb_distal" />
                                                        <site name="S_thumb_tip" pos="0 0 0.026" group="3" size="0.005 0 0" rgba="0.4 0.9 0.4 1"/>
                                                        <site name="Tch_thumb_tip" class="D_Touch" pos="0 -0.004 0.018"/> 
                                                </body>
                                        </body>
                                </body>
                        </body>

                        <body name="R_index_proximal" pos="0.405441 0.554025 0.74897" quat="-0.00212755 -0.0173224 0.992416 0.121677">
                                <inertial pos="0.0099008 0.011884 0.0016958" quat="0.629448 0.777042 2.20645e-05 -2.45535e-05" mass="0.0042403" diaginertia="6.9398e-07 6.62877e-07 2.10913e-07" />
                                <joint name="R_index_MCP_joint" pos="0 0 0" axis="1 0 0" limited="true" range="0 1.7" armature="0.001" frictionloss="0.001" damping="0.05"/>
                                <geom name="C_index_proximal" class="DC_Hand"  type="mesh" contype="0" conaffinity="0" group="1" rgba="1 1 1 1" mesh="R_index_proximal" />
                                <geom name="V_index_proximal" class="D_Vizual" type="mesh" rgba="1 1 1 1" mesh="R_index_proximal" />
                                <site name="S_index_bottom" pos="0 0 0.026" group="3" size="0.005 0 0" rgba="0.4 0.9 0.4 1"/>
                                <site name="Tch_index_botom" class="D_Touch" pos="0 -0.004 0.018"/>   

                                <body name="R_index_distal" pos="0.001575 0.030445 0.010275" quat="0.999755 0.0221422 0 0">
                                        <inertial pos="0.0083258 0.019591 0.0019565" quat="0.581929 0.813239 4.32051e-07 6.03786e-07" mass="0.0045683" diaginertia="7.8179e-07 7.72465e-07 8.47248e-08" />
                                        <joint name="R_index_DIP_joint" pos="0 0 0" axis="1 0 0" limited="true" range="0 1.6" armature="0.001" frictionloss="0.001" damping="0.05"/>
                                        <geom name="C_index_distal" class="DC_Hand"  type="mesh" contype="0" conaffinity="0" group="1" rgba="1 1 1 1" mesh="R_index_distal" />
                                        <geom name="V_index_distal" class="D_Vizual" type="mesh" rgba="1 1 1 1" mesh="R_index_distal" />
                                        <site name="S_index_tip" pos="0 0 0.026" group="3" size="0.005 0 0" rgba="0.4 0.9 0.4 1"/>
                                        <site name="Tch_index_tip" class="D_Touch" pos="0 -0.004 0.018"/>  
                                </body>
                        </body>

                        <body name="R_middle_proximal" pos="0.422932 0.554042 0.74897" quat="-3.64455e-06 4.57949e-07 0.992198 0.124673">
                                <inertial pos="0.008065 0.011884 0.0016958" quat="0.629448 0.777042 2.15784e-05 -2.62734e-05" mass="0.0042403" diaginertia="6.9397e-07 6.62866e-07 2.10914e-07" />
                                <joint name="R_middle_MCP_joint" pos="0 0 0" axis="1 0 0" limited="true" range="0 1.7" armature="0.001" frictionloss="0.001" damping="0.05" />
                                <geom name="C_middle_proximal" class="DC_Hand"  type="mesh" contype="0" conaffinity="0" group="1" rgba="1 1 1 1" mesh="R_middle_proximal" />
                                <geom name="V_middle_proximal" class="D_Vizual" type="mesh" rgba="1 1 1 1" mesh="R_middle_proximal" />
                                <site name="S_middle_bottom" pos="0 0 0.026" group="3" size="0.005 0 0" rgba="0.4 0.9 0.4 1"/>
                                <site name="Tch_middle_botom" class="D_Touch" pos="0 -0.004 0.018"/>   

                                <body name="R_middle_distal" pos="0.0016673 0.030445 0.010275" quat="0.999363 0.0356989 0 0">
                                        <inertial pos="0.0063978 0.020807 0.0018039" quat="0.589614 0.807685 -6.23875e-05 4.98373e-05" mass="0.0050396" diaginertia="9.8384e-07 9.73281e-07 9.13985e-08" />
                                        <joint name="R_middle_DIP_joint" pos="0 0 0" axis="1 0 0" limited="true" range="0 1.6" armature="0.001" frictionloss="0.001" damping="0.05"/>
                                        <geom name="C_middle_distal" class="DC_Hand"  type="mesh" contype="0" conaffinity="0" group="1" rgba="1 1 1 1" mesh="R_middle_distal"/>
                                        <geom name="V_middle_distal" class="D_Vizual" type="mesh" rgba="1 1 1 1" mesh="R_middle_distal" />
                                        <site name="S_middle_tip" pos="0 0 0.026" group="3" size="0.005 0 0" rgba="0.4 0.9 0.4 1"/>
                                        <site name="Tch_middle_tip" class="D_Touch" pos="0 -0.004 0.018"/>  
                                </body>
                        </body>

                        <body name="R_ring_proximal" pos="0.442106 0.553119 0.74897" quat="0.00325992 0.0259732 0.991858 0.12463">
                                <inertial pos="0.0080207 0.011884 0.0016959" quat="0.629449 0.777042 1.88154e-05 -2.40552e-05" mass="0.0042403" diaginertia="6.9397e-07 6.62866e-07 2.10914e-07" />
                                <joint name="R_ring_MCP_joint" pos="0 0 0" axis="1 0 0" limited="true" range="0 1.7" armature="0.001" frictionloss="0.001" damping="0.05"/>
                                <geom name="C_ring_proximal" class="DC_Hand"  type="mesh" contype="0" conaffinity="0" group="1" rgba="1 1 1 1" mesh="R_ring_proximal" />
                                <geom name="V_ring_proximal" class="D_Vizual" type="mesh" rgba="1 1 1 1" mesh="R_ring_proximal" />
                                <site name="S_ring_bottom" pos="0 0 0.026" group="3" size="0.005 0 0" rgba="0.4 0.9 0.4 1"/>
                                <site name="Tch_ring_botom" class="D_Touch" pos="0 -0.004 0.018"/>   

                                <body name="R_ring_distal" pos="0 0.030445 0.010275" quat="0.999803 0.0198727 0 0">
                                        <inertial pos="0.0080209 0.019591 0.0019565" quat="0.581926 0.813242 0 0" mass="0.0045683" diaginertia="7.8177e-07 7.72447e-07 8.47227e-08" />
                                        <joint name="R_ring_DIP_joint" pos="0 0 0" axis="1 0 0" limited="true" range="0 1.6" armature="0.001" frictionloss="0.001" damping="0.05"/>
                                        <geom name="C_ring_distal" class="DC_Hand"  type="mesh" contype="0" conaffinity="0" group="1" rgba="1 1 1 1" mesh="R_ring_distal" />
                                        <geom name="V_ring_distal" class="D_Vizual" type="mesh" rgba="1 1 1 1" mesh="R_ring_distal" />
                                        <site name="S_ring_tip" pos="0 0 0.026" group="3" size="0.005 0 0" rgba="0.4 0.9 0.4 1"/>
                                        <site name="Tch_ring_tip" class="D_Touch" pos="0 -0.004 0.018"/>   
                                </body>
                        </body>

                        <body name="R_pinky_proximal" pos="0.461118 0.551205 0.74897" quat="-0.00652853 -0.0519273 -0.990838 -0.124502">
                                <inertial pos="0.0078887 0.011884 0.0016959" quat="0.629449 0.777042 2.01737e-05 -2.54775e-05" mass="0.0042403" diaginertia="6.9397e-07 6.62866e-07 2.10914e-07" />
                                <joint name="R_pinky_MCP_joint" pos="0 0 0" axis="1 0 0" limited="true" range="0 1.7" armature="0.001" frictionloss="0.001" damping="0.05"/>
                                <geom name="C_pinky_proximal" class="DC_Hand"  type="mesh" contype="0" conaffinity="0" group="1" rgba="1 1 1 1" mesh="R_pinky_proximal" />
                                <geom name="V_pinky_proximal" class="D_Vizual" type="mesh" rgba="1 1 1 1" mesh="R_pinky_proximal" />
                                <site name="S_pinky_bottom" pos="0 0 0.026" group="3" size="0.005 0 0" rgba="0.4 0.9 0.4 1"/>
                                <site name="Tch_pinky_botom" class="D_Touch" pos="0 -0.004 0.018"/>   

                                <body name="R_pinky_distal" pos="0 0.030445 0.010275" quat="0.999822 -0.0188444 0 0">
                                        <inertial pos="0.0078857 0.016239 0.0022243" quat="0.553304 0.832968 0.0036878 -0.00236477" mass="0.0035996" diaginertia="4.4867e-07 4.43716e-07 6.56536e-08" />
                                        <joint name="R_pinky_DIP_joint" pos="0 0 0" axis="1 0 0" limited="true" range="0 1.6" armature="0.001" frictionloss="0.001" damping="0.05"/>
                                        <geom name="C_pinky_distal" class="DC_Hand"  type="mesh" contype="0" conaffinity="0" group="1" rgba="1 1 1 1" mesh="R_pinky_distal" />
                                        <geom name="V_pinky_distal" class="D_Vizual" type="mesh" rgba="1 1 1 1" mesh="R_pinky_distal" />
                                        <site name="S_pinky_tip" pos="0 0 0.026" group="3" size="0.005 0 0" rgba="0.4 0.9 0.4 1"/>
                                        <site name="Tch_pinky_tip" class="D_Touch" pos="0 -0.004 0.018"/>   
                                </body>
                        </body>
                </body>
        </worldbody>

        <contact>
                <pair geom1="C_thumb_distal" geom2="C_hand" condim="1"/>
                <pair geom1="C_thumb_intermediate" geom2="C_hand" condim="1"/>
                <pair geom1="C_thumb_proximal" geom2="C_hand" condim="1"/>
                <pair geom1="C_thumb_proximal_base" geom2="C_hand" condim="1"/>

                <!-- Finger bottom colliding with Thumb tip,middle and base -->
                <pair geom1="C_index_proximal"  geom2="C_thumb_distal" condim="1"/>
                <pair geom1="C_middle_proximal" geom2="C_thumb_distal" condim="1"/>
                <pair geom1="C_ring_proximal"   geom2="C_thumb_distal" condim="1"/>
                <pair geom1="C_pinky_proximal"  geom2="C_thumb_distal" condim="1"/>

                <pair geom1="C_index_proximal"  geom2="C_thumb_intermediate" condim="1"/>
                <pair geom1="C_middle_proximal" geom2="C_thumb_intermediate" condim="1"/>
                <pair geom1="C_ring_proximal"   geom2="C_thumb_intermediate" condim="1"/>
                <pair geom1="C_pinky_proximal"  geom2="C_thumb_intermediate" condim="1"/>

                <pair geom1="C_index_proximal" geom2="C_thumb_proximal" condim="1"/>
                <pair geom1="C_middle_proximal" geom2="C_thumb_proximal" condim="1"/>
                <pair geom1="C_ring_proximal" geom2="C_thumb_proximal" condim="1"/>
                <pair geom1="C_pinky_proximal" geom2="C_thumb_proximal" condim="1"/>

                <!-- Finger tips colliding with Thumb tip,middle and lower -->
                <pair geom1="C_index_distal"  geom2="C_thumb_distal" condim="1"/>
                <pair geom1="C_middle_distal" geom2="C_thumb_distal" condim="1"/>
                <pair geom1="C_ring_distal"   geom2="C_thumb_distal" condim="1"/>
                <pair geom1="C_pinky_distal"  geom2="C_thumb_distal" condim="1"/>

                <pair geom1="C_index_distal"  geom2="C_thumb_intermediate" condim="1"/>
                <pair geom1="C_middle_distal" geom2="C_thumb_intermediate" condim="1"/>
                <pair geom1="C_ring_distal"   geom2="C_thumb_intermediate" condim="1"/>
                <pair geom1="C_pinky_distal"  geom2="C_thumb_intermediate" condim="1"/>

                <pair geom1="C_index_distal"  geom2="C_thumb_proximal" condim="1"/>
                <pair geom1="C_middle_distal" geom2="C_thumb_proximal" condim="1"/>
                <pair geom1="C_ring_distal"   geom2="C_thumb_proximal" condim="1"/>
                <pair geom1="C_pinky_distal"  geom2="C_thumb_proximal" condim="1"/>
        </contact>    



        <actuator>
                <general biasprm="0 -200 0 0 0 0 0 0 0 0" biastype="affine" ctrllimited="true" ctrlrange="-0.75 0.75"
                        gainprm="50 0 0 0 0 0 0 0 0 0" joint="ARTx" name="A_ARTx"
                        user="0 1 0.03 0.0939711 0.513477 0.0358776 1.23598 8.40409 0.485031 6.04244 1.02187 0.175297 0.121642 0 0 0" />
                <general biasprm="0 -200 0 0 0 0 0 0 0 0" biastype="affine" ctrllimited="true" ctrlrange="0 0.75"
                        gainprm="50 0 0 0 0 0 0 0 0 0" joint="ARTy" name="A_ARTy"
                        user="0 1 0.03 0.0939711 0.513477 0.0358776 1.23598 8.40409 0.485031 6.04244 1.02187 0.175297 0.121642 0 0 0" />
                <general biasprm="0 -200 0 0 0 0 0 0 0 0" biastype="affine" ctrllimited="true" ctrlrange="-0.75 0.75"
                        gainprm="50 0 0 0 0 0 0 0 0 0" joint="ARTz" name="A_ARTz"
                        user="0 1 0.03 0.0939711 0.513477 0.0358776 1.23598 8.40409 0.485031 6.04244 1.02187 0.175297 0.121642 0 0 0" />

                <general biasprm="0 -200 0 0 0 0 0 0 0 0" biastype="affine" ctrllimited="true" ctrlrange="-0.4 0.4"
                        gainprm="60 0 0 0 0 0 0 0 0 0" joint="ARRx" name="A_ARRx"
                        user="0 1 0.03 0.0939711 0.513477 0.0358776 1.23598 8.40409 0.485031 6.04244 1.02187 0.175297 0.121642 0 0 0" />
                <general biasprm="0 -200 0 0 0 0 0 0 0 0" biastype="affine" ctrllimited="true" ctrlrange="-0.25 0.25"
                        gainprm="50 0 0 0 0 0 0 0 0 0" joint="ARRy" name="A_ARRy"
                        user="0 1 0.03 0.0939711 0.513477 0.0358776 1.23598 8.40409 0.485031 6.04244 1.02187 0.175297 0.121642 0 0 0" />
                <general biasprm="0 -200 0 0 0 0 0 0 0 0" biastype="affine" ctrllimited="true" ctrlrange="-0.75 0.75"
                        gainprm="50 0 0 0 0 0 0 0 0 0" joint="ARRz" name="A_ARRz"
                        user="0 1 0.03 0.0939711 0.513477 0.0358776 1.23598 8.40409 0.485031 6.04244 1.02187 0.175297 0.121642 0 0 0" />


                <general gainprm="1.5 0 0 0 0 0 0 0 0 0" biasprm="0 -1 0 0 0 0 0 0 0 0" biastype="affine" name="index"      joint="R_index_MCP_joint"   ctrllimited="true" ctrlrange="0 1.1"       
                        user="1002 0 2001 -0.1 0.1 0 0 0 0 0 0 0 0 0 0 0"/>
                <general gainprm="8 0 0 0 0 0 0 0 0 0" biasprm="0 -1 0 0 0 0 0 0 0 0" biastype="affine" name="index_tip"  joint="R_index_DIP_joint"   ctrllimited="true" ctrlrange="0 0.25" 
                        user="1002 0 2001 -0.1 0.1 0 0 0 0 0 0 0 0 0 0 0"/>

                <general gainprm="1.5 0 0 0 0 0 0 0 0 0" biasprm="0 -1 0 0 0 0 0 0 0 0" biastype="affine" name="middle"     joint="R_middle_MCP_joint"  ctrllimited="true" ctrlrange="0 1.1"       
                        user="1002 0 2001 -0.1 0.1 0 0 0 0 0 0 0 0 0 0 0"/>
                <general gainprm="8 0 0 0 0 0 0 0 0 0" biasprm="0 -1 0 0 0 0 0 0 0 0" biastype="affine" name="middle_tip" joint="R_middle_DIP_joint"  ctrllimited="true" ctrlrange="0 0.25"
                        user="1002 0 2001 -0.1 0.1 0 0 0 0 0 0 0 0 0 0 0"/>

                <general gainprm="1.5 0 0 0 0 0 0 0 0 0" biasprm="0 -1 0 0 0 0 0 0 0 0" biastype="affine" name="ring"       joint="R_ring_MCP_joint"    ctrllimited="true" ctrlrange="0 1.1"
                        user="1002 0 2001 -0.1 0.1 0 0 0 0 0 0 0 0 0 0 0"/>
                <general gainprm="8 0 0 0 0 0 0 0 0 0" biasprm="0 -1 0 0 0 0 0 0 0 0" biastype="affine" name="ring_tip"   joint="R_ring_DIP_joint"    ctrllimited="true" ctrlrange="0 0.25" 
                        user="1002 0 2001 -0.1 0.1 0 0 0 0 0 0 0 0 0 0 0"/>

                <general gainprm="1.5 0 0 0 0 0 0 0 0 0" biasprm="0 -1 0 0 0 0 0 0 0 0" biastype="affine" name="pinky"      joint="R_pinky_MCP_joint"   ctrllimited="true" ctrlrange="0 1.1"         
                        user="1002 0 2001 -0.1 0.1 0 0 0 0 0 0 0 0 0 0 0"/>
                <general gainprm="8 0 0 0 0 0 0 0 0 0" biasprm="0 -1 0 0 0 0 0 0 0 0" biastype="affine" name="pinky_tip"  joint="R_pinky_DIP_joint"   ctrllimited="true" ctrlrange="0 0.25" 
                        user="1002 0 2001 -0.1 0.1 0 0 0 0 0 0 0 0 0 0 0"/>



                <general biasprm="0 -1 0 0 0 0 0 0 0 0" biastype="affine" name="thumb_rotate"  joint="R_thumb_MCP_joint1"  ctrllimited="true" ctrlrange="0 2" 
                        user="1002 0 2001 -0.1 0.1 0 0 0 0 0 0 0 0 0 0 0" />
                <general biasprm="0 -1 0 0 0 0 0 0 0 0" biastype="affine" name="thumb_lower"   joint="R_thumb_MCP_joint2"  ctrllimited="true" ctrlrange="0 1" 
                        user="1002 0 2001 -0.1 0.1 0 0 0 0 0 0 0 0 0 0 0" />
                <general biasprm="0 -1 0 0 0 0 0 0 0 0" biastype="affine" name="thumb_middle"  joint="R_thumb_PIP_joint"   ctrllimited="true" ctrlrange="0 0.5" 
                        user="1002 0 2001 -0.1 0.1 0 0 0 0 0 0 0 0 0 0 0" />
                <general biasprm="0 -1 0 0 0 0 0 0 0 0" biastype="affine" name="thumb_tip"     joint="R_thumb_DIP_joint"   ctrllimited="true" ctrlrange="0 0.5" 
                        user="1002 0 2001 -0.1 0.1 0 0 0 0 0 0 0 0 0 0 0" />

        </actuator> 

        <sensor>
                <actuatorfrc actuator="index" name="Saf_index"/>
                <actuatorfrc actuator="index_tip" name="Saf_index_tip"/>
                <actuatorfrc actuator="middle" name="Saf_middle"/>
                <actuatorfrc actuator="middle_tip" name="Saf_middle_tip"/>
                <actuatorfrc actuator="ring" name="Saf_A_ring"/>
                <actuatorfrc actuator="ring_tip" name="Saf_A_ring_tip"/>
                <actuatorfrc actuator="pinky" name="Saf_A_pinky"/>
                <actuatorfrc actuator="pinky_tip" name="Saf_A_pinky_tip"/>
                <actuatorfrc actuator="thumb_rotate" name="Saf_A_thumb_rotate"/>
                <actuatorfrc actuator="thumb_lower" name="Saf_A_thumb_lower"/>
                <actuatorfrc actuator="thumb_middle" name="Saf_A_thumb_middle"/>
                <actuatorfrc actuator="thumb_tip" name="Saf_A_thumb_tip"/>

                <touch site="Tch_index_tip" name="ST_Tch_index_tip"/>
                <touch site="Tch_middle_tip" name="ST_Tch_middle_tip"/>
                <touch site="Tch_ring_tip" name="ST_Tch_ring_tip"/>
                <touch site="Tch_pinky_tip" name="ST_Tch_pinky_tip"/>
                <touch site="Tch_thumb_tip" name="ST_Tch_thumb_tip"/>

                <touch site="Tch_index_botom" name="ST_Tch_index_botom"/>
                <touch site="Tch_middle_botom" name="ST_Tch_middle_botom"/>
                <touch site="Tch_ring_botom" name="ST_Tch_ring_botom"/>
                <touch site="Tch_pinky_botom" name="ST_Tch_pinky_botom"/>
                <touch site="Tch_thumb_bottom" name="ST_Tch_thumb_bottom"/>


                <jointpos joint="R_index_MCP_joint"  name="Sjp_index"/>
                <jointpos joint="R_index_DIP_joint"  name="Sjp_index_tip"/>
                <jointpos joint="R_middle_MCP_joint" name="Sjp_middle"/>
                <jointpos joint="R_middle_DIP_joint" name="Sjp_middle_tip"/>
                <jointpos joint="R_ring_MCP_joint"   name="Sjp_ring"/>
                <jointpos joint="R_ring_DIP_joint"   name="Sjp_ring_tip"/>
                <jointpos joint="R_pinky_MCP_joint"  name="Sjp_pinky"/>
                <jointpos joint="R_pinky_DIP_joint"  name="Sjp_pinky_tip"/>
                <jointpos joint="R_thumb_MCP_joint1" name="Sjp_thumb_rotate"/>
                <jointpos joint="R_thumb_MCP_joint2" name="Sjp_thumb_lower"/>
                <jointpos joint="R_thumb_PIP_joint"  name="Sjp_thumb_middle"/>
                <jointpos joint="R_thumb_DIP_joint"  name="Sjp_thumb_tip"/>

        </sensor>

</mujoco>
